[2019-05-31 13:51:19 +0800] [4314] [INFO] Starting gunicorn 19.9.0
[2019-05-31 13:51:19 +0800] [4314] [INFO] Listening at: http://127.0.0.1:9000 (4314)
[2019-05-31 13:51:19 +0800] [4314] [INFO] Using worker: gevent
[2019-05-31 13:51:19 +0800] [4317] [INFO] Booting worker with pid: 4317
[2019-05-31 13:51:19 +0800] [4318] [INFO] Booting worker with pid: 4318
Traceback (most recent call last):
  File "/home/ubuntu/.virtualenvs/env/lib/python3.5/site-packages/gunicorn/arbiter.py", line 210, in run
    self.sleep()
  File "/home/ubuntu/.virtualenvs/env/lib/python3.5/site-packages/gunicorn/arbiter.py", line 360, in sleep
    ready = select.select([self.PIPE[0]], [], [], 1.0)
  File "/home/ubuntu/.virtualenvs/env/lib/python3.5/site-packages/gunicorn/arbiter.py", line 245, in handle_chld
    self.reap_workers()
  File "/home/ubuntu/.virtualenvs/env/lib/python3.5/site-packages/gunicorn/arbiter.py", line 525, in reap_workers
    raise HaltServer(reason, self.WORKER_BOOT_ERROR)
gunicorn.errors.HaltServer: <HaltServer 'Worker failed to boot.' 3>

During handling of the above exception, another exception occurred:

Traceback (most recent call last):
  File "/home/ubuntu/.virtualenvs/env/bin/gunicorn", line 10, in <module>
    sys.exit(run())
  File "/home/ubuntu/.virtualenvs/env/lib/python3.5/site-packages/gunicorn/app/wsgiapp.py", line 61, in run
    WSGIApplication("%(prog)s [OPTIONS] [APP_MODULE]").run()
  File "/home/ubuntu/.virtualenvs/env/lib/python3.5/site-packages/gunicorn/app/base.py", line 223, in run
    super(Application, self).run()
  File "/home/ubuntu/.virtualenvs/env/lib/python3.5/site-packages/gunicorn/app/base.py", line 72, in run
    Arbiter(self).run()
  File "/home/ubuntu/.virtualenvs/env/lib/python3.5/site-packages/gunicorn/arbiter.py", line 232, in run
    self.halt(reason=inst.reason, exit_status=inst.exit_status)
  File "/home/ubuntu/.virtualenvs/env/lib/python3.5/site-packages/gunicorn/arbiter.py", line 345, in halt
    self.stop()
  File "/home/ubuntu/.virtualenvs/env/lib/python3.5/site-packages/gunicorn/arbiter.py", line 393, in stop
    time.sleep(0.1)
  File "/home/ubuntu/.virtualenvs/env/lib/python3.5/site-packages/gunicorn/arbiter.py", line 245, in handle_chld
    self.reap_workers()
  File "/home/ubuntu/.virtualenvs/env/lib/python3.5/site-packages/gunicorn/arbiter.py", line 525, in reap_workers
    raise HaltServer(reason, self.WORKER_BOOT_ERROR)
gunicorn.errors.HaltServer: <HaltServer 'Worker failed to boot.' 3>
